Workbook

Sheet Orders
A1: order_id | B1: order_date | C1: promised_date | D1: ship_date | E1: deliver_date | F1: customer_id | G1: region | H1: product_id | I1: category | J1: units_ordered | K1: units_shipped | L1: unit_price | M1: discount_rate | N1: shipping_method | O1: warehouse_id | P1: defect_flag | Q1: defect_type | R1: return_flag | S1: lead_time_days | T1: late_days | U1: in_full_flag | V1: otif_flag | W1: revenue | X1: WeekStart | Y1: LatenessCategory | Z1: Xlookup
A2: O0000001 | B2: 45619 | C2: 45624 | D2: 45619 | E2: 45626 | F2: C01127 | G2: South | H2: P00105 | I2: Home | J2: 2 | K2: 2 | L2: 29.65 | M2: 0 | N2: Standard | O2: WH-A | P2: 0 | R2: 0 | S2: 7 | T2: 2 | U2: 1 | V2: 0 | W2: 59.3 | X2: 45613 | Y2: 1–2 days | Z2: =_xlfn.XLOOKUP(synthetic_small[[#This Row],[product_id]],DimProduct!A:A,DimProduct!B:B, "N/A",0) -> Home
A3: O0000002 | B3: 45506 | C3: 45511 | D3: 45507 | E3: 45507 | F3: C02414 | G3: East | H3: P00164 | I3: Electronics | J3: 2 | K3: 2 | L3: 246.94 | M3: 0 | N3: Standard | O3: WH-D | P3: 0 | R3: 0 | S3: 1 | T3: 0 | U3: 1 | V3: 1 | W3: 493.88 | X3: 45501 | Y3: On Time | Z3: =_xlfn.XLOOKUP(synthetic_small[[#This Row],[product_id]],DimProduct!A:A,DimProduct!B:B, "N/A",0) -> Electronics
A4: O0000003 | B4: 45427 | C4: 45429 | D4: 45427 | E4: 45428 | F4: C01882 | G4: North | H4: P00301 | I4: Toys | J4: 1 | K4: 1 | L4: 13.94 | M4: 0 | N4: Expedited | O4: WH-C | P4: 0 | R4: 0 | S4: 1 | T4: 0 | U4: 1 | V4: 1 | W4: 13.94 | X4: 45424 | Y4: On Time | Z4: =_xlfn.XLOOKUP(synthetic_small[[#This Row],[product_id]],DimProduct!A:A,DimProduct!B:B, "N/A",0) -> Toys
A5: O0000004 | B5: 45524 | C5: 45529 | D5: 45524 | E5: 45529 | F5: C01495 | G5: South | H5: P00687 | I5: Sports | J5: 2 | K5: 2 | L5: 76.84 | M5: 0 | N5: Standard | O5: WH-C | P5: 0 | R5: 0 | S5: 5 | T5: 0 | U5: 1 | V5: 1 | W5: 153.68 | X5: 45522 | Y5: On Time | Z5: =_xlfn.XLOOKUP(synthetic_small[[#This Row],[product_id]],DimProduct!A:A,DimProduct!B:B, "N/A",0) -> Sports
A6: O0000005 | B6: 45619 | C6: 45624 | D6: 45620 | E6: 45625 | F6: C00900 | G6: East | H6: P00033 | I6: Electronics | J6: 2 | K6: 2 | L6: 130.39 | M6: 0 | N6: Standard | O6: WH-C | P6: 0 | R6: 0 | S6: 6 | T6: 1 | U6: 1 | V6: 0 | W6: 260.78 | X6: 45613 | Y6: 1–2 days | Z6: =_xlfn.XLOOKUP(synthetic_small[[#This Row],[product_id]],DimProduct!A:A,DimProduct!B:B, "N/A",0) -> Electronics
A7: O0000006 | B7: 45621 | C7: 45626 | D7: 45621 | E7: 45623 | F7: C01085 | G7: South | H7: P00552 | I7: Home | J7: 2 | K7: 2 | L7: 93.22 | M7: 0 | N7: Standard | O7: WH-C | P7: 0 | R7: 0 | S7: 2 | T7: 0 | U7: 1 | V7: 1 | W7: 186.44 | X7: 45620 | Y7: On Time | Z7: =_xlfn.XLOOKUP(synthetic_small[[#This Row],[product_id]],DimProduct!A:A,DimProduct!B:B, "N/A",0) -> Home
A8: O0000007 | B8: 45348 | C8: 45353 | D8: 45348 | E8: 45354 | F8: C00656 | G8: West | H8: P00611 | I8: Electronics | J8: 1 | K8: 1 | L8: 164.65 | M8: 0.23 | N8: Standard | O8: WH-D | P8: 0 | R8: 0 | S8: 6 | T8: 1 | U8: 1 | V8: 0 | W8: 126.78 | X8: 45347 | Y8: 1–2 days | Z8: =_xlfn.XLOOKUP(synthetic_small[[#This Row],[product_id]],DimProduct!A:A,DimProduct!B:B, "N/A",0) -> Electronics
A9: O0000008 | B9: 45466 | C9: 45471 | D9: 45466 | E9: 45472 | F9: C01781 | G9: South | H9: P00740 | I9: Toys | J9: 6 | K9: 6 | L9: 10.16 | M9: 0.21 | N9: Standard | O9: WH-C | P9: 0 | R9: 0 | S9: 6 | T9: 1 | U9: 1 | V9: 0 | W9: 48.16 | X9: 45466 | Y9: 1–2 days | Z9: =_xlfn.XLOOKUP(synthetic_small[[#This Row],[product_id]],DimProduct!A:A,DimProduct!B:B, "N/A",0) -> Toys
A10: O0000009 | B10: 45374 | C10: 45379 | D10: 45374 | E10: 45379 | F10: C02173 | G10: North | H10: P00115 | I10: Sports | J10: 5 | K10: 5 | L10: 98.18 | M10: 0.27 | N10: Standard | O10: WH-C | P10: 0 | R10: 0 | S10: 5 | T10: 0 | U10: 1 | V10: 1 | W10: 358.36 | X10: 45368 | Y10: On Time | Z10: =_xlfn.XLOOKUP(synthetic_small[[#This Row],[product_id]],DimProduct!A:A,DimProduct!B:B, "N/A",0) -> Sports
A11: O0000010 | B11: 45564 | C11: 45566 | D11: 45564 | E11: 45567 | F11: C00526 | G11: West | H11: P00622 | I11: Home | J11: 7 | K11: 7 | L11: 42.83 | M11: 0 | N11: Expedited | O11: WH-D | P11: 0 | R11: 0 | S11: 3 | T11: 1 | U11: 1 | V11: 0 | W11: 299.81 | X11: 45564 | Y11: 1–2 days | Z11: =_xlfn.XLOOKUP(synthetic_small[[#This Row],[product_id]],DimProduct!A:A,DimProduct!B:B, "N/A",0) -> Home
A12: O0000011 | B12: 45516 | C12: 45518 | D12: 45516 | E12: 45518 | F12: C01850 | G12: North | H12: P00347 | I12: Home | J12: 1 | K12: 1 | L12: 38.59 | M12: 0.21 | N12: Expedited | O12: WH-A | P12: 0 | R12: 0 | S12: 2 | T12: 0 | U12: 1 | V12: 1 | W12: 30.49 | X12: 45515 | Y12: On Time | Z12: =_xlfn.XLOOKUP(synthetic_small[[#This Row],[product_id]],DimProduct!A:A,DimProduct!B:B, "N/A",0) -> Home
A13: O0000012 | B13: 45413 | C13: 45418 | D13: 45415 | E13: 45416 | F13: C01989 | G13: South | H13: P00585 | I13: Home | J13: 3 | K13: 3 | L13: 90.95 | M13: 0.21 | N13: Standard | O13: WH-D | P13: 0 | R13: 0 | S13: 3 | T13: 0 | U13: 1 | V13: 1 | W13: 215.55 | X13: 45410 | Y13: On Time | Z13: =_xlfn.XLOOKUP(synthetic_small[[#This Row],[product_id]],DimProduct!A:A,DimProduct!B:B, "N/A",0) -> Home
... A32: O0000031 | B32: 45433 | C32: 45435 | D32: 45434 | E32: 45435 | F32: C02136 | G32: West | H32: P00080 | I32: Home | J32: 3 | K32: 3 | L32: 43.83 | M32: 0.09 | N32: Expedited | O32: WH-C | P32: 0 | R32: 0 | S32: 2 | T32: 0 | U32: 1 | V32: 1 | W32: 119.66 | X32: 45431 | Y32: On Time | Z32: =_xlfn.XLOOKUP(synthetic_small[[#This Row],[product_id]],DimProduct!A:A,DimProduct!B:B, "N/A",0) -> Home
A33: O0000032 | B33: 45500 | C33: 45505 | D33: 45500 | E33: 45505 | F33: C01909 | G33: West | H33: P00431 | I33: Electronics | J33: 5 | K33: 5 | L33: 125.5 | M33: 0 | N33: Standard | O33: WH-D | P33: 1 | Q33: Missing Parts | R33: 0 | S33: 5 | T33: 0 | U33: 1 | V33: 1 | W33: 627.5 | X33: 45494 | Y33: On Time | Z33: =_xlfn.XLOOKUP(synthetic_small[[#This Row],[product_id]],DimProduct!A:A,DimProduct!B:B, "N/A",0) -> Electronics
A34: O0000033 | B34: 45491 | C34: 45493 | D34: 45492 | E34: 45492 | F34: C01717 | G34: South | H34: P00447 | I34: Toys | J34: 4 | K34: 4 | L34: 20.97 | M34: 0 | N34: Expedited | O34: WH-D | P34: 0 | R34: 0 | S34: 1 | T34: 0 | U34: 1 | V34: 1 | W34: 83.88 | X34: 45487 | Y34: On Time | Z34: =_xlfn.XLOOKUP(synthetic_small[[#This Row],[product_id]],DimProduct!A:A,DimProduct!B:B, "N/A",0) -> Toys
A35: O0000034 | B35: 45565 | C35: 45570 | D35: 45566 | E35: 45568 | F35: C01614 | G35: North | H35: P00139 | I35: Electronics | J35: 3 | K35: 3 | L35: 221.4 | M35: 0 | N35: Standard | O35: WH-D | P35: 0 | R35: 0 | S35: 3 | T35: 0 | U35: 1 | V35: 1 | W35: 664.2 | X35: 45564 | Y35: On Time | Z35: =_xlfn.XLOOKUP(synthetic_small[[#This Row],[product_id]],DimProduct!A:A,DimProduct!B:B, "N/A",0) -> Electronics
A36: O0000035 | B36: 45507 | C36: 45512 | D36: 45508 | E36: 45509 | F36: C00336 | G36: West | H36: P00054 | I36: Electronics | J36: 3 | K36: 3 | L36: 244.79 | M36: 0.06 | N36: Standard | O36: WH-C | P36: 1 | Q36: Wrong Item | R36: 0 | S36: 2 | T36: 0 | U36: 1 | V36: 1 | W36: 690.31 | X36: 45501 | Y36: On Time | Z36: =_xlfn.XLOOKUP(synthetic_small[[#This Row],[product_id]],DimProduct!A:A,DimProduct!B:B, "N/A",0) -> Electronics
A37: O0000036 | B37: 45534 | C37: 45539 | D37: 45536 | E37: 45538 | F37: C02311 | G37: South | H37: P00786 | I37: Toys | J37: 4 | K37: 4 | L37: 44.97 | M37: 0.25 | N37: Standard | O37: WH-C | P37: 0 | R37: 0 | S37: 4 | T37: 0 | U37: 1 | V37: 1 | W37: 134.91 | X37: 45529 | Y37: On Time | Z37: =_xlfn.XLOOKUP(synthetic_small[[#This Row],[product_id]],DimProduct!A:A,DimProduct!B:B, "N/A",0) -> Toys
A38: O0000037 | B38: 45484 | C38: 45489 | D38: 45484 | E38: 45485 | F38: C00813 | G38: North | H38: P00792 | I38: Home | J38: 4 | K38: 4 | L38: 25.7 | M38: 0 | N38: Standard | O38: WH-C | P38: 0 | R38: 0 | S38: 1 | T38: 0 | U38: 1 | V38: 1 | W38: 102.8 | X38: 45480 | Y38: On Time | Z38: =_xlfn.XLOOKUP(synthetic_small[[#This Row],[product_id]],DimProduct!A:A,DimProduct!B:B, "N/A",0) -> Home
A39: O0000038 | B39: 45551 | C39: 45556 | D39: 45551 | E39: 45554 | F39: C00052 | G39: West | H39: P00371 | I39: Toys | J39: 2 | K39: 2 | L39: 15.28 | M39: 0 | N39: Standard | O39: WH-D | P39: 0 | R39: 0 | S39: 3 | T39: 0 | U39: 1 | V39: 1 | W39: 30.56 | X39: 45550 | Y39: On Time | Z39: =_xlfn.XLOOKUP(synthetic_small[[#This Row],[product_id]],DimProduct!A:A,DimProduct!B:B, "N/A",0) -> Toys
A40: O0000039 | B40: 45530 | C40: 45535 | D40: 45530 | E40: 45534 | F40: C02427 | G40: East | H40: P00089 | I40: Sports | J40: 4 | K40: 4 | L40: 156.27 | M40: 0 | N40: Standard | O40: WH-C | P40: 0 | R40: 0 | S40: 4 | T40: 0 | U40: 1 | V40: 1 | W40: 625.08 | X40: 45529 | Y40: On Time | Z40: =_xlfn.XLOOKUP(synthetic_small[[#This Row],[product_id]],DimProduct!A:A,DimProduct!B:B, "N/A",0) -> Sports
A41: O0000040 | B41: 45541 | C41: 45546 | D41: 45541 | E41: 45545 | F41: C01059 | G41: East | H41: P00719 | I41: Sports | J41: 1 | K41: 1 | L41: 160.85 | M41: 0 | N41: Standard | O41: WH-C | P41: 0 | R41: 0 | S41: 4 | T41: 0 | U41: 1 | V41: 1 | W41: 160.85 | X41: 45536 | Y41: On Time | Z41: =_xlfn.XLOOKUP(synthetic_small[[#This Row],[product_id]],DimProduct!A:A,DimProduct!B:B, "N/A",0) -> Sports
A42: O0000041 | B42: 45622 | C42: 45624 | D42: 45624 | E42: 45624 | F42: C01836 | G42: North | H42: P00415 | I42: Electronics | J42: 2 | K42: 2 | L42: 144.73 | M42: 0 | N42: Expedited | O42: WH-B | P42: 0 | R42: 0 | S42: 2 | T42: 0 | U42: 1 | V42: 1 | W42: 289.46 | X42: 45620 | Y42: On Time | Z42: =_xlfn.XLOOKUP(synthetic_small[[#This Row],[product_id]],DimProduct!A:A,DimProduct!B:B, "N/A",0) -> Electronics
A43: O0000042 | B43: 45524 | C43: 45529 | D43: 45524 | E43: 45527 | F43: C01030 | G43: South | H43: P00324 | I43: Electronics | J43: 2 | K43: 2 | L43: 238.68 | M43: 0.23 | N43: Standard | O43: WH-A | P43: 0 | R43: 0 | S43: 3 | T43: 0 | U43: 1 | V43: 1 | W43: 367.57 | X43: 45522 | Y43: On Time | Z43: =_xlfn.XLOOKUP(synthetic_small[[#This Row],[product_id]],DimProduct!A:A,DimProduct!B:B, "N/A",0) -> Electronics
A44: O0000043 | B44: 45436 | C44: 45438 | D44: 45436 | E44: 45439 | F44: C00796 | G44: East | H44: P00310 | I44: Home | J44: 2 | K44: 1 | L44: 52.89 | M44: 0 | N44: Expedited | O44: WH-A | P44: 0 | R44: 0 | S44: 3 | T44: 1 | U44: 0 | V44: 0 | W44: 52.89 | X44: 45431 | Y44: 1–2 days | Z44: =_xlfn.XLOOKUP(synthetic_small[[#This Row],[product_id]],DimProduct!A:A,DimProduct!B:B, "N/A",0) -> Home
A45: O0000044 | B45: 45344 | C45: 45346 | D45: 45344 | E45: 45347 | F45: C02352 | G45: East | H45: P00349 | I45: Toys | J45: 4 | K45: 4 | L45: 33.94 | M45: 0.07 | N45: Expedited | O45: WH-B | P45: 0 | R45: 0 | S45: 3 | T45: 1 | U45: 1 | V45: 0 | W45: 126.26 | X45: 45340 | Y45: 1–2 days | Z45: =_xlfn.XLOOKUP(synthetic_small[[#This Row],[product_id]],DimProduct!A:A,DimProduct!B:B, "N/A",0) -> Toys
A46: O0000045 | B46: 45447 | C46: 45452 | D46: 45447 | E46: 45452 | F46: C01017 | G46: North | H46: P00634 | I46: Toys | J46: 3 | K46: 3 | L46: 40.32 | M46: 0 | N46: Standard | O46: WH-B | P46: 0 | R46: 0 | S46: 5 | T46: 0 | U46: 1 | V46: 1 | W46: 120.96 | X46: 45445 | Y46: On Time | Z46: =_xlfn.XLOOKUP(synthetic_small[[#This Row],[product_id]],DimProduct!A:A,DimProduct!B:B, "N/A",0) -> Toys
A47: O0000046 | B47: 45604 | C47: 45606 | D47: 45606 | E47: 45607 | F47: C00407 | G47: South | H47: P00084 | I47: Home | J47: 3 | K47: 3 | L47: 42.79 | M47: 0 | N47: Expedited | O47: WH-B | P47: 0 | R47: 0 | S47: 3 | T47: 1 | U47: 1 | V47: 0 | W47: 128.37 | X47: 45599 | Y47: 1–2 days | Z47: =_xlfn.XLOOKUP(synthetic_small[[#This Row],[product_id]],DimProduct!A:A,DimProduct!B:B, "N/A",0) -> Home
A48: O0000047 | B48: 45653 | C48: 45658 | D48: 45654 | E48: 45657 | F48: C01860 | G48: North | H48: P00641 | I48: Home | J48: 1 | K48: 1 | L48: 112.01 | M48: 0 | N48: Standard | O48: WH-B | P48: 0 | R48: 0 | S48: 4 | T48: 0 | U48: 1 | V48: 1 | W48: 112.01 | X48: 45648 | Y48: On Time | Z48: =_xlfn.XLOOKUP(synthetic_small[[#This Row],[product_id]],DimProduct!A:A,DimProduct!B:B, "N/A",0) -> Home
... A67: O0000066 | B67: 45567 | C67: 45572 | D67: 45567 | E67: 45573 | F67: C01859 | G67: East | H67: P00745 | I67: Toys | J67: 5 | K67: 5 | L67: 39.37 | M67: 0 | N67: Standard | O67: WH-B | P67: 0 | R67: 0 | S67: 6 | T67: 1 | U67: 1 | V67: 0 | W67: 196.85 | X67: 45564 | Y67: 1–2 days | Z67: =_xlfn.XLOOKUP(synthetic_small[[#This Row],[product_id]],DimProduct!A:A,DimProduct!B:B, "N/A",0) -> Toys
A68: O0000067 | B68: 45412 | C68: 45414 | D68: 45412 | E68: 45415 | F68: C00407 | G68: East | H68: P00283 | I68: Sports | J68: 7 | K68: 7 | L68: 29.69 | M68: 0.1 | N68: Expedited | O68: WH-B | P68: 1 | Q68: Missing Parts | R68: 0 | S68: 3 | T68: 1 | U68: 1 | V68: 0 | W68: 187.05 | X68: 45410 | Y68: 1–2 days | Z68: =_xlfn.XLOOKUP(synthetic_small[[#This Row],[product_id]],DimProduct!A:A,DimProduct!B:B, "N/A",0) -> Sports
A69: O0000068 | B69: 45356 | C69: 45358 | D69: 45356 | E69: 45357 | F69: C00841 | G69: North | H69: P00239 | I69: Home | J69: 3 | K69: 3 | L69: 76.57 | M69: 0 | N69: Expedited | O69: WH-C | P69: 0 | R69: 0 | S69: 1 | T69: 0 | U69: 1 | V69: 1 | W69: 229.71 | X69: 45354 | Y69: On Time | Z69: =_xlfn.XLOOKUP(synthetic_small[[#This Row],[product_id]],DimProduct!A:A,DimProduct!B:B, "N/A",0) -> Home
A70: O0000069 | B70: 45348 | C70: 45353 | D70: 45349 | E70: 45349 | F70: C00106 | G70: South | H70: P00244 | I70: Electronics | J70: 4 | K70: 4 | L70: 158.81 | M70: 0 | N70: Standard | O70: WH-C | P70: 0 | R70: 0 | S70: 1 | T70: 0 | U70: 1 | V70: 1 | W70: 635.24 | X70: 45347 | Y70: On Time | Z70: =_xlfn.XLOOKUP(synthetic_small[[#This Row],[product_id]],DimProduct!A:A,DimProduct!B:B, "N/A",0) -> Electronics
A71: O0000070 | B71: 45554 | C71: 45559 | D71: 45555 | E71: 45558 | F71: C01852 | G71: South | H71: P00675 | I71: Electronics | J71: 1 | K71: 1 | L71: 239.99 | M71: 0 | N71: Standard | O71: WH-C | P71: 0 | R71: 0 | S71: 4 | T71: 0 | U71: 1 | V71: 1 | W71: 239.99 | X71: 45550 | Y71: On Time | Z71: =_xlfn.XLOOKUP(synthetic_small[[#This Row],[product_id]],DimProduct!A:A,DimProduct!B:B, "N/A",0) -> Electronics
A72: O0000071 | B72: 45519 | C72: 45524 | D72: 45520 | E72: 45524 | F72: C00331 | G72: East | H72: P00282 | I72: Home | J72: 1 | K72: 1 | L72: 21.9 | M72: 0 | N72: Standard | O72: WH-C | P72: 0 | R72: 0 | S72: 5 | T72: 0 | U72: 1 | V72: 1 | W72: 21.9 | X72: 45515 | Y72: On Time | Z72: =_xlfn.XLOOKUP(synthetic_small[[#This Row],[product_id]],DimProduct!A:A,DimProduct!B:B, "N/A",0) -> Home
A73: O0000072 | B73: 45574 | C73: 45576 | D73: 45574 | E73: 45576 | F73: C00881 | G73: West | H73: P00424 | I73: Toys | J73: 3 | K73: 3 | L73: 54.4 | M73: 0 | N73: Expedited | O73: WH-C | P73: 0 | R73: 0 | S73: 2 | T73: 0 | U73: 1 | V73: 1 | W73: 163.2 | X73: 45571 | Y73: On Time | Z73: =_xlfn.XLOOKUP(synthetic_small[[#This Row],[product_id]],DimProduct!A:A,DimProduct!B:B, "N/A",0) -> Toys
A74: O0000073 | B74: 45534 | C74: 45539 | D74: 45534 | E74: 45537 | F74: C00350 | G74: North | H74: P00757 | I74: Toys | J74: 3 | K74: 3 | L74: 14.83 | M74: 0 | N74: Standard | O74: WH-C | P74: 0 | R74: 0 | S74: 3 | T74: 0 | U74: 1 | V74: 1 | W74: 44.49 | X74: 45529 | Y74: On Time | Z74: =_xlfn.XLOOKUP(synthetic_small[[#This Row],[product_id]],DimProduct!A:A,DimProduct!B:B, "N/A",0) -> Toys
A75: O0000074 | B75: 45508 | C75: 45510 | D75: 45509 | E75: 45511 | F75: C00211 | G75: East | H75: P00592 | I75: Sports | J75: 4 | K75: 4 | L75: 76.26 | M75: 0 | N75: Expedited | O75: WH-B | P75: 0 | R75: 0 | S75: 3 | T75: 1 | U75: 1 | V75: 0 | W75: 305.04 | X75: 45508 | Y75: 1–2 days | Z75: =_xlfn.XLOOKUP(synthetic_small[[#This Row],[product_id]],DimProduct!A:A,DimProduct!B:B, "N/A",0) -> Sports
A76: O0000075 | B76: 45511 | C76: 45513 | D76: 45511 | E76: 45512 | F76: C02281 | G76: North | H76: P00280 | I76: Sports | J76: 4 | K76: 4 | L76: 24.63 | M76: 0.21 | N76: Expedited | O76: WH-C | P76: 0 | R76: 0 | S76: 1 | T76: 0 | U76: 1 | V76: 1 | W76: 77.83 | X76: 45508 | Y76: On Time | Z76: =_xlfn.XLOOKUP(synthetic_small[[#This Row],[product_id]],DimProduct!A:A,DimProduct!B:B, "N/A",0) -> Sports
...

Sheet DimProduct
A1: product_id | B1: category
A2: P00105 | B2: Home
A3: P00164 | B3: Electronics
A4: P00301 | B4: Toys
A5: P00687 | B5: Sports
A6: P00033 | B6: Electronics
A7: P00552 | B7: Home
A8: P00611 | B8: Electronics
A9: P00740 | B9: Toys
A10: P00115 | B10: Sports
A11: P00622 | B11: Home
A12: P00347 | B12: Home
... A799: P00748 | B799: Home

Sheet Pivot_OTIF
A1: WeekStart | B1: (All)
A3: Sum of otif_flag | B3: Column Labels
A4: Row Labels | B4: Expedited | C4: Standard | D4: Grand Total
A5: East | B5: 211 | C5: 620 | D5: 831
A6: North | B6: 217 | C6: 619 | D6: 836
A7: South | B7: 219 | C7: 628 | D7: 847
A8: West | B8: 222 | C8: 664 | D8: 886
A9: Grand Total | B9: 869 | C9: 2531 | D9: 3400
